Workbook
Name DadosExternos_1: Sabia!$A$1:$O$19
Name DadosExternos_1: metricas_media!$A$1:$O$235
Name DadosExternos_1: Phi!$A$1:$O$37
Name DadosExternos_1: 'gabmetricas_redações_diplomatas'!$A$1:$O$235
Name DadosExternos_1: Llama!$A$1:$O$37
Name DadosExternos_1: Gemma!$A$1:$O$37
Name DadosExternos_1: Command!$A$1:$O$19
Name DadosExternos_1: Qwen!$A$1:$O$37
Name DadosExternos_1: 'metricas_redações_diplomatas'!$A$1:$O$235
Name DadosExternos_1: Mixtral!$A$1:$O$37
Name DadosExternos_1: GPT!$A$1:$O$19

Sheet metricas_redações_diplomatas
A1: id | B1: modification_type | C1: generator_model | D1: BLEU_score | E1: BERTScore_Precision | F1: BERTScore_Recall | G1: BERTScore_F1 | H1: rouge1 | I1: rouge2 | J1: rougeL | K1: rougeLsum | L1: CTC_groundness | M1: CTC_groundness_ref | N1: CTC_factual | O1: CTC_factual_ref
A2: 0_Ana Luiza | B2: texto_prompt_0 | C2: gpt4o_temp03 | D2: 0.090745485 | E2: 0.75012708 | F2: 0.75142026 | G2: 0.75077313 | H2: 0.53077302 | I2: 0.17841301 | J2: 0.19005416 | K2: 0.28163466 | L2: 0 | M2: 0 | N2: 0.99999994 | O2: 0.82713348
A3: 0_Ana Luiza | B3: texto_prompt_0 | C3: gpt4o_temp05 | D3: 0.094385792 | E3: 0.74998558 | F3: 0.75218433 | G3: 0.75108337 | H3: 0.53071253 | I3: 0.17314314 | J3: 0.19262899 | K3: 0.28206388 | L3: 0 | M3: 0 | N3: 0.99999994 | O3: 0.82713348
A4: 0_Ana Luiza | B4: texto_prompt_0 | C4: gpt4o_temp07 | D4: 0.088738595 | E4: 0.75095534 | F4: 0.7501893 | G4: 0.75057214 | H4: 0.53100597 | I4: 0.1691954 | J4: 0.19384474 | K4: 0.28479559 | L4: 0 | M4: 0 | N4: 0.99999994 | O4: 0.82713348
A5: 0_Ana Luiza | B5: texto_prompt_0 | C5: command_r_plus_08_2024_temp03 | D5: 0.070257996 | E5: 0.73955077 | F5: 0.73888868 | G5: 0.73921955 | H5: 0.51017964 | I5: 0.16906475 | J5: 0.18562874 | K5: 0.28263473 | L5: 0 | M5: 0 | N5: 0.99999994 | O5: 0.82713348
A6: 0_Ana Luiza | B6: texto_prompt_0 | C6: command_r_plus_08_2024_temp05 | D6: 0.071549664 | E6: 0.73747015 | F6: 0.73935527 | G6: 0.73841149 | H6: 0.50630011 | I6: 0.15137615 | J6: 0.20274914 | K6: 0.27720504 | L6: 0 | M6: 0 | N6: 0.99999994 | O6: 0.82713348
A7: 0_Ana Luiza | B7: texto_prompt_0 | C7: command_r_plus_08_2024_temp07 | D7: 0.060182739 | E7: 0.75066757 | F7: 0.74399567 | G7: 0.74731678 | H7: 0.4852071 | I7: 0.13744076 | J7: 0.19053254 | K7: 0.29230769 | L7: 0 | M7: 0 | N7: 0.99999994 | O7: 0.82713348
A8: 0_Ana Luiza | B8: texto_prompt_0 | C8: gemma_27b_temp03 | D8: 0.056423145 | E8: 0.7438938 | F8: 0.7367084 | G8: 0.74028367 | H8: 0.47607053 | I8: 0.15762926 | J8: 0.17884131 | K8: 0.26952141 | L8: 0 | M8: 0 | N8: 0.99999994 | O8: 0.82713348
A9: 0_Ana Luiza | B9: texto_prompt_0 | C9: gemma_27b_temp05 | D9: 0.055889326 | E9: 0.7473039 | F9: 0.73746061 | G9: 0.74234957 | H9: 0.46857143 | I9: 0.15511761 | J9: 0.1752381 | K9: 0.26793651 | L9: 0 | M9: 0 | N9: 0.99999994 | O9: 0.82713348
A10: 0_Ana Luiza | B10: texto_prompt_0 | C10: gemma_27b_temp07 | D10: 0.055889326 | E10: 0.7473039 | F10: 0.73746061 | G10: 0.74234957 | H10: 0.46857143 | I10: 0.15511761 | J10: 0.1752381 | K10: 0.26793651 | L10: 0 | M10: 0 | N10: 0.99999994 | O10: 0.82713348
A11: 0_Ana Luiza | B11: texto_prompt_0 | C11: gemma_9b_temp03 | D11: 0.057153719 | E11: 0.75805134 | F11: 0.75195205 | G11: 0.75498939 | H11: 0.48188175 | I11: 0.15404201 | J11: 0.20470439 | K11: 0.2619199 | L11: 0 | M11: 0 | N11: 0.99999994 | O11: 0.82713348
A12: 0_Ana Luiza | B12: texto_prompt_0 | C12: gemma_9b_temp05 | D12: 0.051347904 | E12: 0.75961924 | F12: 0.74994045 | G12: 0.75474882 | H12: 0.49044586 | I12: 0.16071429 | J12: 0.20382166 | K12: 0.2611465 | L12: 0 | M12: 0 | N12: 0.99999994 | O12: 0.82713348
A13: 0_Ana Luiza | B13: texto_prompt_0 | C13: gemma_9b_temp07 | D13: 0.047294785 | E13: 0.75837189 | F13: 0.74990022 | G13: 0.75411224 | H13: 0.48063033 | I13: 0.16305062 | J13: 0.19829284 | K13: 0.26526592 | L13: 0 | M13: 0 | N13: 0.99999994 | O13: 0.82713348
... A235: 5_Pedro Guilherme | B235: texto_prompt_0 | C235: sabia3_temp07 | D235: 0.069367757 | E235: 0.74829322 | F235: 0.72431046 | G235: 0.73610651 | H235: 0.54924515 | I235: 0.18718503 | J235: 0.1984184 | K235: 0.30050324 | L235: 0 | M235: 0 | N235: 0.99999994 | O235: 0.99999994

Sheet gabmetricas_redações_diplomatas
A1: id | B1: modification_type | C1: generator_model | D1: BLEU_score | E1: BERTScore_Precision | F1: BERTScore_Recall | G1: BERTScore_F1 | H1: rouge1 | I1: rouge2 | J1: rougeL | K1: rougeLsum | L1: CTC_groundness | M1: CTC_groundness_ref | N1: CTC_factual | O1: CTC_factual_ref
A2: 0_Ana Luiza | B2: texto_prompt_0 | C2: gpt4o_temp03 | D2: 0.090745485 | E2: 0.75012708 | F2: 0.75142026 | G2: 0.75077313 | H2: 0.53077302 | I2: 0.17841301 | J2: 0.19005416 | K2: 0.28163466 | L2: 0 | M2: 0 | N2: 0.99999994 | O2: 0.82713348
A3: 0_Ana Luiza | B3: texto_prompt_0 | C3: gpt4o_temp05 | D3: 0.094385792 | E3: 0.74998558 | F3: 0.75218433 | G3: 0.75108337 | H3: 0.53071253 | I3: 0.17314314 | J3: 0.19262899 | K3: 0.28206388 | L3: 0 | M3: 0 | N3: 0.99999994 | O3: 0.82713348
A4: 0_Ana Luiza | B4: texto_prompt_0 | C4: gpt4o_temp07 | D4: 0.088738595 | E4: 0.75095534 | F4: 0.7501893 | G4: 0.75057214 | H4: 0.53100597 | I4: 0.1691954 | J4: 0.19384474 | K4: 0.28479559 | L4: 0 | M4: 0 | N4: 0.99999994 | O4: 0.82713348
A5: 0_Ana Luiza | B5: texto_prompt_0 | C5: command_r_plus_08_2024_temp03 | D5: 0.070257996 | E5: 0.73955077 | F5: 0.73888868 | G5: 0.73921955 | H5: 0.51017964 | I5: 0.16906475 | J5: 0.18562874 | K5: 0.28263473 | L5: 0 | M5: 0 | N5: 0.99999994 | O5: 0.82713348
A6: 0_Ana Luiza | B6: texto_prompt_0 | C6: command_r_plus_08_2024_temp05 | D6: 0.071549664 | E6: 0.73747015 | F6: 0.73935527 | G6: 0.73841149 | H6: 0.50630011 | I6: 0.15137615 | J6: 0.20274914 | K6: 0.27720504 | L6: 0 | M6: 0 | N6: 0.99999994 | O6: 0.82713348
A7: 0_Ana Luiza | B7: texto_prompt_0 | C7: command_r_plus_08_2024_temp07 | D7: 0.060182739 | E7: 0.75066757 | F7: 0.74399567 | G7: 0.74731678 | H7: 0.4852071 | I7: 0.13744076 | J7: 0.19053254 | K7: 0.29230769 | L7: 0 | M7: 0 | N7: 0.99999994 | O7: 0.82713348
A8: 0_Ana Luiza | B8: texto_prompt_0 | C8: gemma_27b_temp03 | D8: 0.056423145 | E8: 0.7438938 | F8: 0.7367084 | G8: 0.74028367 | H8: 0.47607053 | I8: 0.15762926 | J8: 0.17884131 | K8: 0.26952141 | L8: 0 | M8: 0 | N8: 0.99999994 | O8: 0.82713348
A9: 0_Ana Luiza | B9: texto_prompt_0 | C9: gemma_27b_temp05 | D9: 0.055889326 | E9: 0.7473039 | F9: 0.73746061 | G9: 0.74234957 | H9: 0.46857143 | I9: 0.15511761 | J9: 0.1752381 | K9: 0.26793651 | L9: 0 | M9: 0 | N9: 0.99999994 | O9: 0.82713348
A10: 0_Ana Luiza | B10: texto_prompt_0 | C10: gemma_27b_temp07 | D10: 0.055889326 | E10: 0.7473039 | F10: 0.73746061 | G10: 0.74234957 | H10: 0.46857143 | I10: 0.15511761 | J10: 0.1752381 | K10: 0.26793651 | L10: 0 | M10: 0 | N10: 0.99999994 | O10: 0.82713348
A11: 0_Ana Luiza | B11: texto_prompt_0 | C11: gemma_9b_temp03 | D11: 0.057153719 | E11: 0.75805134 | F11: 0.75195205 | G11: 0.75498939 | H11: 0.48188175 | I11: 0.15404201 | J11: 0.20470439 | K11: 0.2619199 | L11: 0 | M11: 0 | N11: 0.99999994 | O11: 0.82713348
A12: 0_Ana Luiza | B12: texto_prompt_0 | C12: gemma_9b_temp05 | D12: 0.051347904 | E12: 0.75961924 | F12: 0.74994045 | G12: 0.75474882 | H12: 0.49044586 | I12: 0.16071429 | J12: 0.20382166 | K12: 0.2611465 | L12: 0 | M12: 0 | N12: 0.99999994 | O12: 0.82713348
A13: 0_Ana Luiza | B13: texto_prompt_0 | C13: gemma_9b_temp07 | D13: 0.047294785 | E13: 0.75837189 | F13: 0.74990022 | G13: 0.75411224 | H13: 0.48063033 | I13: 0.16305062 | J13: 0.19829284 | K13: 0.26526592 | L13: 0 | M13: 0 | N13: 0.99999994 | O13: 0.82713348
... A235: 5_Pedro Guilherme | B235: texto_prompt_0 | C235: sabia3_temp07 | D235: 0.069367757 | E235: 0.74829322 | F235: 0.72431046 | G235: 0.73610651 | H235: 0.54924515 | I235: 0.18718503 | J235: 0.1984184 | K235: 0.30050324 | L235: 0 | M235: 0 | N235: 0.99999994 | O235: 0.99999994

Sheet metricas_media
A1: id | B1: modification_type | C1: generator_model | D1: BLEU_score | E1: BERTScore_Precision | F1: BERTScore_Recall | G1: BERTScore_F1 | H1: rouge1 | I1: rouge2 | J1: rougeL | K1: rougeLsum | L1: CTC_groundness | M1: CTC_groundness_ref | N1: CTC_factual | O1: CTC_factual_ref | Q1: Médias
A2: 0_Ana Luiza | B2: texto_prompt_0 | C2: command_r_plus_08_2024_temp03 | D2: 0.070257996 | E2: 0.73955077 | F2: 0.73888868 | G2: 0.73921955 | H2: 0.51017964 | I2: 0.16906475 | J2: 0.18562874 | K2: 0.28263473 | L2: 0 | M2: 0 | N2: 0.99999994 | O2: 0.82713348 | Q2: Modelo | R2: Bleu | S2: Bertscore_precision | T2: Bertscore_Recall | U2: Bertscore_F1 | V2: Rouge1 | W2: Rouge2 | X2: RougeL | Y2: RougeLsum | Z2: CTC_Factual | AA2: CTC_FactualRef
A3: 1_Gabriel Joaquim | B3: texto_prompt_0 | C3: command_r_plus_08_2024_temp03 | D3: 0.048696623 | E3: 0.71414721 | F3: 0.69722587 | G3: 0.70558506 | H3: 0.45527452 | I3: 0.12353305 | J3: 0.17396669 | K3: 0.27760642 | L3: 0 | M3: 0 | N3: 0.99999994 | O3: 0.55453807 | Q3: Command_r_plus_08_2024_temp03 | R3: =AVERAGE(D2:D7) -> 0.061024437 | S3: =AVERAGE(E2:E7) -> 0.72392994 | T3: =AVERAGE(F2:F7) -> 0.71699755 | U3: =AVERAGE(G2:G7) -> 0.72043185 | V3: =AVERAGE(H2:H7) -> 0.47675211 | W3: =AVERAGE(I2:I7) -> 0.13532263 | X3: =AVERAGE(J2:J7) -> 0.18632606 | Y3: =AVERAGE(K2:K7) -> 0.2742143 | Z3: =AVERAGE(N2:N7) -> 0.99999994 | AA3: =AVERAGE(O2:O7) -> 0.89694522
A4: 2_Leonardo Maciura | B4: texto_prompt_0 | C4: command_r_plus_08_2024_temp03 | D4: 0.06763447 | E4: 0.73315519 | F4: 0.7267713 | G4: 0.7299493 | H4: 0.47862157 | I4: 0.14185304 | J4: 0.2003829 | K4: 0.27185705 | L4: 0 | M4: 0 | N4: 0.99999994 | O4: 0.99999994 | Q4: Command_r_plus_08_2024_temp05 | R4: =AVERAGE(D8:D13) -> 0.069589304 | S4: =AVERAGE(E8:E13) -> 0.7299664 | T4: =AVERAGE(F8:F13) -> 0.72712937 | U4: =AVERAGE(G8:G13) -> 0.72853348 | V4: =AVERAGE(H8:H13) -> 0.49455032 | W4: =AVERAGE(I8:I13) -> 0.14232316 | X4: =AVERAGE(J8:J13) -> 0.19762614 | Y4: =AVERAGE(K8:K13) -> 0.28161236 | Z4: =AVERAGE(N8:N13) -> 0.99999994 | AA4: =AVERAGE(O8:O13) -> 0.89694522
A5: 3_Mateus de Andrade | B5: texto_prompt_0 | C5: command_r_plus_08_2024_temp03 | D5: 0.039842204 | E5: 0.713539 | F5: 0.71304846 | G5: 0.71329361 | H5: 0.45076283 | I5: 0.10833333 | J5: 0.18030513 | K5: 0.24271845 | L5: 0 | M5: 0 | N5: 0.99999994 | O5: 0.99999994 | Q5: Command_r_plus_08_2024_temp07 | R5: =AVERAGE(D14:D19) -> 0.060453401 | S5: =AVERAGE(E14:E19) -> 0.73906951 | T5: =AVERAGE(F14:F19) -> 0.72763364 | U5: =AVERAGE(G14:G19) -> 0.73329574 | V5: =AVERAGE(H14:H19) -> 0.47995278 | W5: =AVERAGE(I14:I19) -> 0.12627503 | X5: =AVERAGE(J14:J19) -> 0.18976805 | Y5: =AVERAGE(K14:K19) -> 0.2798468 | Z5: =AVERAGE(N14:N19) -> 0.99999994 | AA5: =AVERAGE(O14:O19) -> 0.89694522
A6: 4_Patrícia Camargo | B6: texto_prompt_0 | C6: command_r_plus_08_2024_temp03 | D6: 0.065798616 | E6: 0.70749223 | F6: 0.70498621 | G6: 0.70623702 | H6: 0.45050215 | I6: 0.11925287 | J6: 0.18077475 | K6: 0.2697274 | L6: 0 | M6: 0 | N6: 0.99999994 | O6: 0.99999994 | Q6: gemma_27b_temp03 | R6: =AVERAGE(D20:D25) -> 0.050699594 | S6: =AVERAGE(E20:E25) -> 0.73621348 | T6: =AVERAGE(F20:F25) -> 0.72278398 | U6: =AVERAGE(G20:G25) -> 0.72942023 | V6: =AVERAGE(H20:H25) -> 0.45857887 | W6: =AVERAGE(I20:I25) -> 0.12361329 | X6: =AVERAGE(J20:J25) -> 0.18487753 | Y6: =AVERAGE(K20:K25) -> 0.27055297 | Z6: =AVERAGE(N20:N25) -> 0.99999994 | AA6: =AVERAGE(O20:O25) -> 0.89694522
A7: 5_Pedro Guilherme | B7: texto_prompt_0 | C7: command_r_plus_08_2024_temp03 | D7: 0.073916714 | E7: 0.73569524 | F7: 0.72106481 | G7: 0.72830659 | H7: 0.51517195 | I7: 0.14989872 | J7: 0.19689818 | K7: 0.30074174 | L7: 0 | M7: 0 | N7: 0.99999994 | O7: 0.99999994 | Q7: gemma_27b_temp05 | R7: =AVERAGE(D26:D31) -> 0.049876311 | S7: =AVERAGE(E26:E31) -> 0.73916959 | T7: =AVERAGE(F26:F31) -> 0.72404964 | U7: =AVERAGE(G26:G31) -> 0.73151462 | V7: =AVERAGE(H26:H31) -> 0.45445128 | W7: =AVERAGE(I26:I31) -> 0.12474439 | X7: =AVERAGE(J26:J31) -> 0.18407197 | Y7: =AVERAGE(K26:K31) -> 0.27166781 | Z7: =AVERAGE(N26:N31) -> 0.99999994 | AA7: =AVERAGE(O26:O31) -> 0.89694522
A8: 0_Ana Luiza | B8: texto_prompt_0 | C8: command_r_plus_08_2024_temp05 | D8: 0.071549664 | E8: 0.73747015 | F8: 0.73935527 | G8: 0.73841149 | H8: 0.50630011 | I8: 0.15137615 | J8: 0.20274914 | K8: 0.27720504 | L8: 0 | M8: 0 | N8: 0.99999994 | O8: 0.82713348 | Q8: gemma_27b_temp07 | R8: =AVERAGE(D32:D37) -> 0.049876311 | S8: =AVERAGE(E32:E37) -> 0.73916959 | T8: =AVERAGE(F32:F37) -> 0.72404964 | U8: =AVERAGE(G32:G37) -> 0.73151462 | V8: =AVERAGE(H32:H37) -> 0.45445128 | W8: =AVERAGE(I32:I37) -> 0.12474439 | X8: =AVERAGE(J32:J37) -> 0.18407197 | Y8: =AVERAGE(K32:K37) -> 0.27166781 | Z8: =AVERAGE(N32:N37) -> 0.99999994 | AA8: =AVERAGE(O32:O37) -> 0.89694522
A9: 1_Gabriel Joaquim | B9: texto_prompt_0 | C9: command_r_plus_08_2024_temp05 | D9: 0.058958918 | E9: 0.71727502 | F9: 0.7088846 | G9: 0.71305513 | H9: 0.47377725 | I9: 0.11563422 | J9: 0.19210371 | K9: 0.27578079 | L9: 0 | M9: 0 | N9: 0.99999994 | O9: 0.55453807 | Q9: gemma_9b_temp03 | R9: =AVERAGE(D38:D43) -> 0.060859236 | S9: =AVERAGE(E38:E43) -> 0.74591008 | T9: =AVERAGE(F38:F43) -> 0.73165295 | U9: =AVERAGE(G38:G43) -> 0.73869164 | V9: =AVERAGE(H38:H43) -> 0.47860582 | W9: =AVERAGE(I38:I43) -> 0.13631004 | X9: =AVERAGE(J38:J43) -> 0.20645161 | Y9: =AVERAGE(K38:K43) -> 0.26297034 | Z9: =AVERAGE(N38:N43) -> 0.99999994 | AA9: =AVERAGE(O38:O43) -> 0.89694522
A10: 2_Leonardo Maciura | B10: texto_prompt_0 | C10: command_r_plus_08_2024_temp05 | D10: 0.075685029 | E10: 0.73533142 | F10: 0.73179972 | G10: 0.73356134 | H10: 0.51369446 | I10: 0.14503352 | J10: 0.21180767 | K10: 0.27267194 | L10: 0 | M10: 0 | N10: 0.99999994 | O10: 0.99999994 | Q10: gemma_9b_temp05 | R10: =AVERAGE(D44:D49) -> 0.059663558 | S10: =AVERAGE(E44:E49) -> 0.74893706 | T10: =AVERAGE(F44:F49) -> 0.73203522 | U10: =AVERAGE(G44:G49) -> 0.74037186 | V10: =AVERAGE(H44:H49) -> 0.48284347 | W10: =AVERAGE(I44:I49) -> 0.1401008 | X10: =AVERAGE(J44:J49) -> 0.20765443 | Y10: =AVERAGE(K44:K49) -> 0.26291312 | Z10: =AVERAGE(N44:N49) -> 0.99999994 | AA10: =AVERAGE(O44:O49) -> 0.89694522
A11: 3_Mateus de Andrade | B11: texto_prompt_0 | C11: command_r_plus_08_2024_temp05 | D11: 0.056358129 | E11: 0.72340077 | F11: 0.7280128 | G11: 0.72569942 | H11: 0.45981555 | I11: 0.11741425 | J11: 0.18577075 | K11: 0.27931489 | L11: 0 | M11: 0 | N11: 0.99999994 | O11: 0.99999994 | Q11: gemma_9b_temp07 | R11: =AVERAGE(D50:D55) -> 0.055548947 | S11: =AVERAGE(E50:E55) -> 0.74816682 | T11: =AVERAGE(F50:F55) -> 0.73208153 | U11: =AVERAGE(G50:G55) -> 0.74001827 | V11: =AVERAGE(H50:H55) -> 0.47645355 | W11: =AVERAGE(I50:I55) -> 0.14025379 | X11: =AVERAGE(J50:J55) -> 0.20444002 | Y11: =AVERAGE(K50:K55) -> 0.26686421 | Z11: =AVERAGE(N50:N55) -> 0.99999994 | AA11: =AVERAGE(O50:O55) -> 0.89694522
A12: 4_Patrícia Camargo | B12: texto_prompt_0 | C12: command_r_plus_08_2024_temp05 | D12: 0.065295119 | E12: 0.72440207 | F12: 0.72480404 | G12: 0.724603 | H12: 0.47619048 | I12: 0.14850136 | J12: 0.19319728 | K12: 0.28707483 | L12: 0 | M12: 0 | N12: 0.99999994 | O12: 0.99999994 | Q12: gpt4o_temp03 | R12: =AVERAGE(D56:D61) -> 0.074004531 | S12: =AVERAGE(E56:E61) -> 0.74133035 | T12: =AVERAGE(F56:F61) -> 0.7353552 | U12: =AVERAGE(G56:G61) -> 0.73831919 | V12: =AVERAGE(H56:H61) -> 0.49396262 | W12: =AVERAGE(I56:I61) -> 0.15234035 | X12: =AVERAGE(J56:J61) -> 0.18676565 | Y12: =AVERAGE(K56:K61) -> 0.26850228 | Z12: =AVERAGE(N56:N61) -> 0.99999994 | AA12: =AVERAGE(O56:O61) -> 0.89694522
A13: 5_Pedro Guilherme | B13: texto_prompt_0 | C13: command_r_plus_08_2024_temp05 | D13: 0.089688963 | E13: 0.74191898 | F13: 0.72991979 | G13: 0.73587048 | H13: 0.53752405 | I13: 0.17597945 | J13: 0.20012829 | K13: 0.29762668 | L13: 0 | M13: 0 | N13: 0.99999994 | O13: 0.99999994 | Q13: gpt4o_temp05 | R13: =AVERAGE(D62:D67) -> 0.075309144 | S13: =AVERAGE(E62:E67) -> 0.74417934 | T13: =AVERAGE(F62:F67) -> 0.73690199 | U13: =AVERAGE(G62:G67) -> 0.74050531 | V13: =AVERAGE(H62:H67) -> 0.49472601 | W13: =AVERAGE(I62:I67) -> 0.15086703 | X13: =AVERAGE(J62:J67) -> 0.18795845 | Y13: =AVERAGE(K62:K67) -> 0.26931955 | Z13: =AVERAGE(N62:N67) -> 0.99999994 | AA13: =AVERAGE(O62:O67) -> 0.89694522
A14: 0_Ana Luiza | B14: texto_prompt_0 | C14: command_r_plus_08_2024_temp07 | D14: 0.060182739 | E14: 0.75066757 | F14: 0.74399567 | G14: 0.74731678 | H14: 0.4852071 | I14: 0.13744076 | J14: 0.19053254 | K14: 0.29230769 | L14: 0 | M14: 0 | N14: 0.99999994 | O14: 0.82713348 | Q14: gpt4o_temp07 | R14: =AVERAGE(D68:D73) -> 0.069793688 | S14: =AVERAGE(E68:E73) -> 0.74347635 | T14: =AVERAGE(F68:F73) -> 0.73428788 | U14: =AVERAGE(G68:G73) -> 0.73884125 | V14: =AVERAGE(H68:H73) -> 0.4787606 | W14: =AVERAGE(I68:I73) -> 0.14857676 | X14: =AVERAGE(J68:J73) -> 0.1843926 | Y14: =AVERAGE(K68:K73) -> 0.26908441 | Z14: =AVERAGE(N68:N73) -> 0.99999994 | AA14: =AVERAGE(O68:O73) -> 0.89694522
A15: 1_Gabriel Joaquim | B15: texto_prompt_0 | C15: command_r_plus_08_2024_temp07 | D15: 0.044627861 | E15: 0.72755706 | F15: 0.70798439 | G15: 0.71763736 | H15: 0.46191347 | I15: 0.10250153 | J15: 0.18037782 | K15: 0.26447288 | L15: 0 | M15: 0 | N15: 0.99999994 | O15: 0.55453807 | Q15: llama_405b_temp03 | R15: =AVERAGE(D74:D79) -> 0.066045053 | S15: =AVERAGE(E74:E79) -> 0.74289767 | T15: =AVERAGE(F74:F79) -> 0.72658866 | U15: =AVERAGE(G74:G79) -> 0.73464081 | V15: =AVERAGE(H74:H79) -> 0.47587057 | W15: =AVERAGE(I74:I79) -> 0.13383424 | X15: =AVERAGE(J74:J79) -> 0.19620772 | Y15: =AVERAGE(K74:K79) -> 0.27224242 | Z15: =AVERAGE(N74:N79) -> 0.99999994 | AA15: =AVERAGE(O74:O79) -> 0.89694522
A16: 2_Leonardo Maciura | B16: texto_prompt_0 | C16: command_r_plus_08_2024_temp07 | D16: 0.06527792 | E16: 0.75196481 | F16: 0.74000585 | G16: 0.74593741 | H16: 0.49653434 | I16: 0.12492114 | J16: 0.19533711 | K16: 0.27851292 | L16: 0 | M16: 0 | N16: 0.99999994 | O16: 0.99999994 | Q16: llama_405b_temp05 | R16: =AVERAGE(D80:D85) -> 0.053168728 | S16: =AVERAGE(E80:E85) -> 0.74186163 | T16: =AVERAGE(F80:F85) -> 0.72506865 | U16: =AVERAGE(G80:G85) -> 0.73335136 | V16: =AVERAGE(H80:H85) -> 0.45567639 | W16: =AVERAGE(I80:I85) -> 0.13081573 | X16: =AVERAGE(J80:J85) -> 0.18833575 | Y16: =AVERAGE(K80:K85) -> 0.2576814 | Z16: =AVERAGE(N80:N85) -> 0.76935196 | AA16: =AVERAGE(O80:O85) -> 0.73003822
A17: 3_Mateus de Andrade | B17: texto_prompt_0 | C17: command_r_plus_08_2024_temp07 | D17: 0.053237143 | E17: 0.73050904 | F17: 0.72732639 | G17: 0.7289142 | H17: 0.45690834 | I17: 0.11232877 | J17: 0.18331053 | K17: 0.27222982 | L17: 0 | M17: 0 | N17: 0.99999994 | O17: 0.99999994 | Q17: llama_405b_temp07 | R17: =AVERAGE(D86:D91) -> 0.061049157 | S17: =AVERAGE(E86:E91) -> 0.74874798 | T17: =AVERAGE(F86:F91) -> 0.71558375 | U17: =AVERAGE(G86:G91) -> 0.7317706 | V17: =AVERAGE(H86:H91) -> 0.43777889 | W17: =AVERAGE(I86:I91) -> 0.1292605 | X17: =AVERAGE(J86:J91) -> 0.19683071 | Y17: =AVERAGE(K86:K91) -> 0.24463209 | Z17: =AVERAGE(N86:N91) -> 0.99999994 | AA17: =AVERAGE(O86:O91) -> 0.89694522
A18: 4_Patrícia Camargo | B18: texto_prompt_0 | C18: command_r_plus_08_2024_temp07 | D18: 0.056876114 | E18: 0.72766572 | F18: 0.7177121 | G18: 0.7226547 | H18: 0.46817539 | I18: 0.12322946 | J18: 0.18811881 | K18: 0.281471 | L18: 0 | M18: 0 | N18: 0.99999994 | O18: 0.99999994 | Q18: llama_8b_temp03 | R18: =AVERAGE(D92:D97) -> 0.054769736 | S18: =AVERAGE(E92:E97) -> 0.73018722 | T18: =AVERAGE(F92:F97) -> 0.71631672 | U18: =AVERAGE(G92:G97) -> 0.72317664 | V18: =AVERAGE(H92:H97) -> 0.48215458 | W18: =AVERAGE(I92:I97) -> 0.12658975 | X18: =AVERAGE(J92:J97) -> 0.19863814 | Y18: =AVERAGE(K92:K97) -> 0.25245911 | Z18: =AVERAGE(N92:N97) -> 0.99999994 | AA18: =AVERAGE(O92:O97) -> 0.89694522
A19: 5_Pedro Guilherme | B19: texto_prompt_0 | C19: command_r_plus_08_2024_temp07 | D19: 0.08251863 | E19: 0.74605286 | F19: 0.72877741 | G19: 0.73731399 | H19: 0.51097804 | I19: 0.15722851 | J19: 0.20093147 | K19: 0.29008649 | L19: 0 | M19: 0 | N19: 0.99999994 | O19: 0.99999994 | Q19: llama_8b_temp05 | R19: =AVERAGE(D98:D103) -> 0.047727942 | S19: =AVERAGE(E98:E103) -> 0.73018722 | T19: =AVERAGE(F98:F103) -> 0.71631672 | U19: =AVERAGE(G98:G103) -> 0.72317664 | V19: =AVERAGE(H98:H103) -> 0.47642744 | W19: =AVERAGE(I98:I103) -> 0.12569677 | X19: =AVERAGE(J98:J103) -> 0.19322574 | Y19: =AVERAGE(K98:K103) -> 0.2431265 | Z19: =AVERAGE(N98:N103) -> 0.99999994 | AA19: =AVERAGE(O98:O103) -> 0.89694522
A20: 0_Ana Luiza | B20: texto_prompt_0 | C20: gemma_27b_temp03 | D20: 0.056423145 | E20: 0.7438938 | F20: 0.7367084 | G20: 0.74028367 | H20: 0.47607053 | I20: 0.15762926 | J20: 0.17884131 | K20: 0.26952141 | L20: 0 | M20: 0 | N20: 0.99999994 | O20: 0.82713348 | Q20: llama_8b_temp07 | R20: =AVERAGE(D104:D109) -> 0.040614952 | S20: =AVERAGE(E104:E109) -> 0.7329401 | T20: =AVERAGE(F104:F109) -> 0.7195558 | U20: =AVERAGE(G104:G109) -> 0.72617856 | V20: =AVERAGE(H104:H109) -> 0.46743035 | W20: =AVERAGE(I104:I109) -> 0.12440016 | X20: =AVERAGE(J104:J109) -> 0.18901305 | Y20: =AVERAGE(K104:K109) -> 0.24919495 | Z20: =AVERAGE(N104:N109) -> 0.99999994 | AA20: =AVERAGE(O104:O109) -> 0.89694522
A21: 1_Gabriel Joaquim | B21: texto_prompt_0 | C21: gemma_27b_temp03 | D21: 0.034471011 | E21: 0.72128767 | F21: 0.70100665 | G21: 0.71100253 | H21: 0.43014945 | I21: 0.097592713 | J21: 0.17283951 | K21: 0.26120858 | L21: 0 | M21: 0 | N21: 0.99999994 | O21: 0.55453807 | Q21: mixtral_8x22_temp03 | R21: =AVERAGE(D110:D115) -> 0.036722019 | S21: =AVERAGE(E110:E115) -> 0.74412478 | T21: =AVERAGE(F110:F115) -> 0.72428196 | U21: =AVERAGE(G110:G115) -> 0.73405338 | V21: =AVERAGE(H110:H115) -> 0.4246946 | W21: =AVERAGE(I110:I115) -> 0.12412494 | X21: =AVERAGE(J110:J115) -> 0.1759705 | Y21: =AVERAGE(K110:K115) -> 0.24540478 | Z21: =AVERAGE(N110:N115) -> 0.99999994 | AA21: =AVERAGE(O110:O115) -> 0.89694522
A22: 2_Leonardo Maciura | B22: texto_prompt_0 | C22: gemma_27b_temp03 | D22: 0.04794497 | E22: 0.74933946 | F22: 0.738765 | G22: 0.74401468 | H22: 0.44444444 | I22: 0.11598112 | J22: 0.19124579 | K22: 0.26262626 | L22: 0 | M22: 0 | N22: 0.99999994 | O22: 0.99999994 | Q22: mixtral_8x22_temp05 | R22: =AVERAGE(D116:D121) -> 0.04781878 | S22: =AVERAGE(E116:E121) -> 0.74437074 | T22: =AVERAGE(F116:F121) -> 0.72745626 | U22: =AVERAGE(G116:G121) -> 0.73580389 | V22: =AVERAGE(H116:H121) -> 0.44022997 | W22: =AVERAGE(I116:I121) -> 0.12779844 | X22: =AVERAGE(J116:J121) -> 0.18271034 | Y22: =AVERAGE(K116:K121) -> 0.25358507 | Z22: =AVERAGE(N116:N121) -> 0.99999994 | AA22: =AVERAGE(O116:O121) -> 0.89694522
A23: 3_Mateus de Andrade | B23: texto_prompt_0 | C23: gemma_27b_temp03 | D23: 0.050480298 | E23: 0.73540312 | F23: 0.72867763 | G23: 0.73202491 | H23: 0.46470588 | I23: 0.11340206 | J23: 0.19117647 | K23: 0.26911765 | L23: 0 | M23: 0 | N23: 0.99999994 | O23: 0.99999994 | Q23: mixtral_8x22_temp07 | R23: =AVERAGE(D122:D127) -> 0.058045029 | S23: =AVERAGE(E122:E127) -> 0.74938586 | T23: =AVERAGE(F122:F127) -> 0.72336134 | U23: =AVERAGE(G122:G127) -> 0.73612185 | V23: =AVERAGE(H122:H127) -> 0.44509221 | W23: =AVERAGE(I122:I127) -> 0.12411555 | X23: =AVERAGE(J122:J127) -> 0.18550747 | Y23: =AVERAGE(K122:K127) -> 0.25891115 | Z23: =AVERAGE(N122:N127) -> 0.76935196 | AA23: =AVERAGE(O122:O127) -> 0.73003822
A24: 4_Patrícia Camargo | B24: texto_prompt_0 | C24: gemma_27b_temp03 | D24: 0.037884232 | E24: 0.72371268 | F24: 0.71305943 | G24: 0.7183466 | H24: 0.44359756 | I24: 0.10839695 | J24: 0.17530488 | K24: 0.26676829 | L24: 0 | M24: 0 | N24: 0.99999994 | O24: 0.99999994 | Q24: mixtral_8x7_temp03 | R24: =AVERAGE(D128:D133) -> 0.05407673 | S24: =AVERAGE(E128:E133) -> 0.73783494 | T24: =AVERAGE(F128:F133) -> 0.71838489 | U24: =AVERAGE(G128:G133) -> 0.72796774 | V24: =AVERAGE(H128:H133) -> 0.47501234 | W24: =AVERAGE(I128:I133) -> 0.13194339 | X24: =AVERAGE(J128:J133) -> 0.19253225 | Y24: =AVERAGE(K128:K133) -> 0.26888738 | Z24: =AVERAGE(N128:N133) -> 0.99999994 | AA24: =AVERAGE(O128:O133) -> 0.89694522
A25: 5_Pedro Guilherme | B25: texto_prompt_0 | C25: gemma_27b_temp03 | D25: 0.076993905 | E25: 0.74364412 | F25: 0.71848679 | G25: 0.73084903 | H25: 0.49250535 | I25: 0.14867763 | J25: 0.19985724 | K25: 0.29407566 | L25: 0 | M25: 0 | N25: 0.99999994 | O25: 0.99999994 | Q25: mixtral_8x7_temp05 | R25: =AVERAGE(D134:D139) -> 0.032505868 | S25: =AVERAGE(E134:E139) -> 0.73765322 | T25: =AVERAGE(F134:F139) -> 0.71832864 | U25: =AVERAGE(G134:G139) -> 0.72784976 | V25: =AVERAGE(H134:H139) -> 0.41405478 | W25: =AVERAGE(I134:I139) -> 0.12021321 | X25: =AVERAGE(J134:J139) -> 0.17652013 | Y25: =AVERAGE(K134:K139) -> 0.23843512 | Z25: =AVERAGE(N134:N139) -> 0.99999994 | AA25: =AVERAGE(O134:O139) -> 0.89694522
A26: 0_Ana Luiza | B26: texto_prompt_0 | C26: gemma_27b_temp05 | D26: 0.055889326 | E26: 0.7473039 | F26: 0.73746061 | G26: 0.74234957 | H26: 0.46857143 | I26: 0.15511761 | J26: 0.1752381 | K26: 0.26793651 | L26: 0 | M26: 0 | N26: 0.99999994 | O26: 0.82713348 | Q26: mixtral_8x7_temp07 | R26: =AVERAGE(D140:D145) -> 0.040552794 | S26: =AVERAGE(E140:E145) -> 0.72820065 | T26: =AVERAGE(F140:F145) -> 0.72684048 | U26: =AVERAGE(G140:G145) -> 0.72748727 | V26: =AVERAGE(H140:H145) -> 0.42650029 | W26: =AVERAGE(I140:I145) -> 0.1146131 | X26: =AVERAGE(J140:J145) -> 0.17497133 | Y26: =AVERAGE(K140:K145) -> 0.24387155 | Z26: =AVERAGE(N140:N145) -> 0.99999994 | AA26: =AVERAGE(O140:O145) -> 0.89694522
A27: 1_Gabriel Joaquim | B27: texto_prompt_0 | C27: gemma_27b_temp05 | D27: 0.035039186 | E27: 0.72421813 | F27: 0.70147038 | G27: 0.71266276 | H27: 0.42463958 | I27: 0.099737533 | J27: 0.17300131 | K27: 0.2542595 | L27: 0 | M27: 0 | N27: 0.99999994 | O27: 0.55453807 | Q27: phi_3.5_vision_temp03 | R27: =AVERAGE(D146:D151) -> 0.018238044 | S27: =AVERAGE(E146:E151) -> 0.74726757 | T27: =AVERAGE(F146:F151) -> 0.7180994 | U27: =AVERAGE(G146:G151) -> 0.73238146 | V27: =AVERAGE(H146:H151) -> 0.34008055 | W27: =AVERAGE(I146:I151) -> 0.1004585 | X27: =AVERAGE(J146:J151) -> 0.15520205 | Y27: =AVERAGE(K146:K151) -> 0.20265998 | Z27: =AVERAGE(N146:N151) -> 0.76935196 | AA27: =AVERAGE(O146:O151) -> 0.73003822
A28: 2_Leonardo Maciura | B28: texto_prompt_0 | C28: gemma_27b_temp05 | D28: 0.058063388 | E28: 0.75547194 | F28: 0.74298131 | G28: 0.74917454 | H28: 0.44429348 | I28: 0.12108844 | J28: 0.19157609 | K28: 0.26494565 | L28: 0 | M28: 0 | N28: 0.99999994 | O28: 0.99999994 | Q28: phi_3.5_vision_temp05 | R28: =AVERAGE(D152:D157) -> 0.018238044 | S28: =AVERAGE(E152:E157) -> 0.74726757 | T28: =AVERAGE(F152:F157) -> 0.7180994 | U28: =AVERAGE(G152:G157) -> 0.73238146 | V28: =AVERAGE(H152:H157) -> 0.34008055 | W28: =AVERAGE(I152:I157) -> 0.1004585 | X28: =AVERAGE(J152:J157) -> 0.15520205 | Y28: =AVERAGE(K152:K157) -> 0.20265998 | Z28: =AVERAGE(N152:N157) -> 0.76935196 | AA28: =AVERAGE(O152:O157) -> 0.73003822
A29: 3_Mateus de Andrade | B29: texto_prompt_0 | C29: gemma_27b_temp05 | D29: 0.046451755 | E29: 0.73841929 | F29: 0.72959125 | G29: 0.73397875 | H29: 0.45731255 | I29: 0.11152416 | J29: 0.19005197 | K29: 0.26726058 | L29: 0 | M29: 0 | N29: 0.99999994 | O29: 0.99999994 | Q29: phi_3.5_vision_temp07 | R29: =AVERAGE(D158:D163) -> 0.017560209 | S29: =AVERAGE(E158:E163) -> 0.74081288 | T29: =AVERAGE(F158:F163) -> 0.71465579 | U29: =AVERAGE(G158:G163) -> 0.72748359 | V29: =AVERAGE(H158:H163) -> 0.35483507 | W29: =AVERAGE(I158:I163) -> 0.10399943 | X29: =AVERAGE(J158:J163) -> 0.16837207 | Y29: =AVERAGE(K158:K163) -> 0.21087876 | Z29: =AVERAGE(N158:N163) -> 0.76935196 | AA29: =AVERAGE(O158:O163) -> 0.73003822
A30: 4_Patrícia Camargo | B30: texto_prompt_0 | C30: gemma_27b_temp05 | D30: 0.031524458 | E30: 0.7248826 | F30: 0.71459371 | G30: 0.71970141 | H30: 0.44341801 | I30: 0.10948342 | J30: 0.17859892 | K30: 0.28021555 | L30: 0 | M30: 0 | N30: 0.99999994 | O30: 0.99999994 | Q30: phi_3_mini_temp03 | R30: =AVERAGE(D164:D169) -> 0.018838425 | S30: =AVERAGE(E164:E169) -> 0.73499081 | T30: =AVERAGE(F164:F169) -> 0.7241942 | U30: =AVERAGE(G164:G169) -> 0.72955082 | V30: =AVERAGE(H164:H169) -> 0.37408176 | W30: =AVERAGE(I164:I169) -> 0.086486731 | X30: =AVERAGE(J164:J169) -> 0.17181114 | Y30: =AVERAGE(K164:K169) -> 0.22209041 | Z30: =AVERAGE(N164:N169) -> 0.7023139 | AA30: =AVERAGE(O164:O169) -> 0.6908719
A31: 5_Pedro Guilherme | B31: texto_prompt_0 | C31: gemma_27b_temp05 | D31: 0.072289754 | E31: 0.74472165 | F31: 0.71820056 | G31: 0.73122072 | H31: 0.48847262 | I31: 0.15151515 | J31: 0.19596542 | K31: 0.29538905 | L31: 0 | M31: 0 | N31: 0.99999994 | O31: 0.99999994 | Q31: phi_3_mini_temp05 | R31: =AVERAGE(D170:D175) -> 0.029596639 | S31: =AVERAGE(E170:E175) -> 0.74136882 | T31: =AVERAGE(F170:F175) -> 0.71860652 | U31: =AVERAGE(G170:G175) -> 0.72978675 | V31: =AVERAGE(H170:H175) -> 0.37850516 | W31: =AVERAGE(I170:I175) -> 0.10543207 | X31: =AVERAGE(J170:J175) -> 0.17174335 | Y31: =AVERAGE(K170:K175) -> 0.22450766 | Z31: =AVERAGE(N170:N175) -> 0.76935196 | AA31: =AVERAGE(O170:O175) -> 0.73003822
A32: 0_Ana Luiza | B32: texto_prompt_0 | C32: gemma_27b_temp07 | D32: 0.055889326 | E32: 0.7473039 | F32: 0.73746061 | G32: 0.74234957 | H32: 0.46857143 | I32: 0.15511761 | J32: 0.1752381 | K32: 0.26793651 | L32: 0 | M32: 0 | N32: 0.99999994 | O32: 0.82713348 | Q32: phi_3_mini_temp07 | R32: =AVERAGE(D176:D181) -> 0.025090594 | S32: =AVERAGE(E176:E181) -> 0.7277146 | T32: =AVERAGE(F176:F181) -> 0.72212866 | U32: =AVERAGE(G176:G181) -> 0.72489832 | V32: =AVERAGE(H176:H181) -> 0.38066746 | W32: =AVERAGE(I176:I181) -> 0.095911001 | X32: =AVERAGE(J176:J181) -> 0.16266309 | Y32: =AVERAGE(K176:K181) -> 0.22763028 | Z32: =AVERAGE(N176:N181) -> 0.82713348 | AA32: =AVERAGE(O176:O181) -> 0.80494425
A33: 1_Gabriel Joaquim | B33: texto_prompt_0 | C33: gemma_27b_temp07 | D33: 0.035039186 | E33: 0.72421813 | F33: 0.70147038 | G33: 0.71266276 | H33: 0.42463958 | I33: 0.099737533 | J33: 0.17300131 | K33: 0.2542595 | L33: 0 | M33: 0 | N33: 0.99999994 | O33: 0.55453807 | Q33: qwen2_72_temp03 | R33: =AVERAGE(D182:D187) -> 0.047035881 | S33: =AVERAGE(E182:E187) -> 0.74305599 | T33: =AVERAGE(F182:F187) -> 0.72778914 | U33: =AVERAGE(G182:G187) -> 0.73533356 | V33: =AVERAGE(H182:H187) -> 0.42123504 | W33: =AVERAGE(I182:I187) -> 0.10484971 | X33: =AVERAGE(J182:J187) -> 0.17953922 | Y33: =AVERAGE(K182:K187) -> 0.25363757 | Z33: =AVERAGE(N182:N187) -> 0.99999994 | AA33: =AVERAGE(O182:O187) -> 0.89694522
A34: 2_Leonardo Maciura | B34: texto_prompt_0 | C34: gemma_27b_temp07 | D34: 0.058063388 | E34: 0.75547194 | F34: 0.74298131 | G34: 0.74917454 | H34: 0.44429348 | I34: 0.12108844 | J34: 0.19157609 | K34: 0.26494565 | L34: 0 | M34: 0 | N34: 0.99999994 | O34: 0.99999994 | Q34: qwen2_72_temp05 | R34: =AVERAGE(D188:D193) -> 0.05072383 | S34: =AVERAGE(E188:E193) -> 0.74301405 | T34: =AVERAGE(F188:F193) -> 0.73140012 | U34: =AVERAGE(G188:G193) -> 0.73713803 | V34: =AVERAGE(H188:H193) -> 0.40021167 | W34: =AVERAGE(I188:I193) -> 0.11174544 | X34: =AVERAGE(J188:J193) -> 0.17239365 | Y34: =AVERAGE(K188:K193) -> 0.2481418 | Z34: =AVERAGE(N188:N193) -> 0.7023139 | AA34: =AVERAGE(O188:O193) -> 0.6908719
A35: 3_Mateus de Andrade | B35: texto_prompt_0 | C35: gemma_27b_temp07 | D35: 0.046451755 | E35: 0.73841929 | F35: 0.72959125 | G35: 0.73397875 | H35: 0.45731255 | I35: 0.11152416 | J35: 0.19005197 | K35: 0.26726058 | L35: 0 | M35: 0 | N35: 0.99999994 | O35: 0.99999994 | Q35: qwen2_72_temp07 | R35: =AVERAGE(D194:D199) -> 0.036314237 | S35: =AVERAGE(E194:E199) -> 0.74390319 | T35: =AVERAGE(F194:F199) -> 0.72968199 | U35: =AVERAGE(G194:G199) -> 0.73669582 | V35: =AVERAGE(H194:H199) -> 0.39750725 | W35: =AVERAGE(I194:I199) -> 0.098539324 | X35: =AVERAGE(J194:J199) -> 0.16965104 | Y35: =AVERAGE(K194:K199) -> 0.22560477 | Z35: =AVERAGE(N194:N199) -> 0.99999994 | AA35: =AVERAGE(O194:O199) -> 0.89694522
A36: 4_Patrícia Camargo | B36: texto_prompt_0 | C36: gemma_27b_temp07 | D36: 0.031524458 | E36: 0.7248826 | F36: 0.71459371 | G36: 0.71970141 | H36: 0.44341801 | I36: 0.10948342 | J36: 0.17859892 | K36: 0.28021555 | L36: 0 | M36: 0 | N36: 0.99999994 | O36: 0.99999994 | Q36: qwen2_7_temp03 | R36: =AVERAGE(D200:D205) -> 0.013243931 | S36: =AVERAGE(E200:E205) -> 0.6604864 | T36: =AVERAGE(F200:F205) -> 0.64377747 | U36: =AVERAGE(G200:G205) -> 0.6520172 | V36: =AVERAGE(H200:H205) -> 0.3384063 | W36: =AVERAGE(I200:I205) -> 0.093735505 | X36: =AVERAGE(J200:J205) -> 0.1685573 | Y36: =AVERAGE(K200:K205) -> 0.18909453 | Z36: =AVERAGE(N200:N205) -> 0.82775801 | AA36: =AVERAGE(O200:O205) -> 0.78744572
A37: 5_Pedro Guilherme | B37: texto_prompt_0 | C37: gemma_27b_temp07 | D37: 0.072289754 | E37: 0.74472165 | F37: 0.71820056 | G37: 0.73122072 | H37: 0.48847262 | I37: 0.15151515 | J37: 0.19596542 | K37: 0.29538905 | L37: 0 | M37: 0 | N37: 0.99999994 | O37: 0.99999994 | Q37: qwen2_7_temp05 | R37: =AVERAGE(D206:D211) -> 0.013243931 | S37: =AVERAGE(E206:E211) -> 0.6604864 | T37: =AVERAGE(F206:F211) -> 0.64377747 | U37: =AVERAGE(G206:G211) -> 0.6520172 | V37: =AVERAGE(H206:H211) -> 0.3384063 | W37: =AVERAGE(I206:I211) -> 0.093735505 | X37: =AVERAGE(J206:J211) -> 0.1685573 | Y37: =AVERAGE(K206:K211) -> 0.18909453 | Z37: =AVERAGE(N206:N211) -> 0.82775801 | AA37: =AVERAGE(O206:O211) -> 0.78744572
A38: 0_Ana Luiza | B38: texto_prompt_0 | C38: gemma_9b_temp03 | D38: 0.057153719 | E38: 0.75805134 | F38: 0.75195205 | G38: 0.75498939 | H38: 0.48188175 | I38: 0.15404201 | J38: 0.20470439 | K38: 0.2619199 | L38: 0 | M38: 0 | N38: 0.99999994 | O38: 0.82713348 | Q38: qwen2_7_temp07 | R38: =AVERAGE(D212:D217) -> 0.024597557 | S38: =AVERAGE(E212:E217) -> 0.74362829 | T38: =AVERAGE(F212:F217) -> 0.71574911 | U38: =AVERAGE(G212:G217) -> 0.72938187 | V38: =AVERAGE(H212:H217) -> 0.37624557 | W38: =AVERAGE(I212:I217) -> 0.10894594 | X38: =AVERAGE(J212:J217) -> 0.16945277 | Y38: =AVERAGE(K212:K217) -> 0.2272884 | Z38: =AVERAGE(N212:N217) -> 0.82775801 | AA38: =AVERAGE(O212:O217) -> 0.78744572
A39: 1_Gabriel Joaquim | B39: texto_prompt_0 | C39: gemma_9b_temp03 | D39: 0.0454294 | E39: 0.72987622 | F39: 0.70777321 | G39: 0.71865481 | H39: 0.46062992 | I39: 0.11038108 | J39: 0.19685039 | K39: 0.25984252 | L39: 0 | M39: 0 | N39: 0.99999994 | O39: 0.55453807 | Q39: sabia3_temp03 | R39: =AVERAGE(D218:D223) -> 0.052779316 | S39: =AVERAGE(E218:E223) -> 0.74902738 | T39: =AVERAGE(F218:F223) -> 0.73930895 | U39: =AVERAGE(G218:G223) -> 0.74411137 | V39: =AVERAGE(H218:H223) -> 0.48680811 | W39: =AVERAGE(I218:I223) -> 0.15126719 | X39: =AVERAGE(J218:J223) -> 0.19207632 | Y39: =AVERAGE(K218:K223) -> 0.26285021 | Z39: =AVERAGE(N218:N223) -> 0.99999994 | AA39: =AVERAGE(O218:O223) -> 0.89694522
A40: 2_Leonardo Maciura | B40: texto_prompt_0 | C40: gemma_9b_temp03 | D40: 0.07846316 | E40: 0.76195771 | F40: 0.74621582 | G40: 0.75400466 | H40: 0.48979592 | I40: 0.15667575 | J40: 0.21632653 | K40: 0.26258503 | L40: 0 | M40: 0 | N40: 0.99999994 | O40: 0.99999994 | Q40: sabia3_temp05 | R40: =AVERAGE(D224:D229) -> 0.070281998 | S40: =AVERAGE(E224:E229) -> 0.74524201 | T40: =AVERAGE(F224:F229) -> 0.73750472 | U40: =AVERAGE(G224:G229) -> 0.74133032 | V40: =AVERAGE(H224:H229) -> 0.51258287 | W40: =AVERAGE(I224:I229) -> 0.14511706 | X40: =AVERAGE(J224:J229) -> 0.1895605 | Y40: =AVERAGE(K224:K229) -> 0.27356926 | Z40: =AVERAGE(N224:N229) -> 0.99999994 | AA40: =AVERAGE(O224:O229) -> 0.89694522
...

Sheet Command
A1: id | B1: modification_type | C1: generator_model | D1: BLEU_score | E1: BERTScore_Precision | F1: BERTScore_Recall | G1: BERTScore_F1 | H1: rouge1 | I1: rouge2 | J1: rougeL | K1: rougeLsum | L1: CTC_groundness | M1: CTC_groundness_ref | N1: CTC_factual | O1: CTC_factual_ref
A2: 0_Ana Luiza | B2: texto_prompt_0 | C2: command_r_plus_08_2024_temp03 | D2: 0.070257996 | E2: 0.73955077 | F2: 0.73888868 | G2: 0.73921955 | H2: 0.51017964 | I2: 0.16906475 | J2: 0.18562874 | K2: 0.28263473 | L2: 0 | M2: 0 | N2: 0.99999994 | O2: 0.82713348
A3: 0_Ana Luiza | B3: texto_prompt_0 | C3: command_r_plus_08_2024_temp05 | D3: 0.071549664 | E3: 0.73747015 | F3: 0.73935527 | G3: 0.73841149 | H3: 0.50630011 | I3: 0.15137615 | J3: 0.20274914 | K3: 0.27720504 | L3: 0 | M3: 0 | N3: 0.99999994 | O3: 0.82713348
A4: 0_Ana Luiza | B4: texto_prompt_0 | C4: command_r_plus_08_2024_temp07 | D4: 0.060182739 | E4: 0.75066757 | F4: 0.74399567 | G4: 0.74731678 | H4: 0.4852071 | I4: 0.13744076 | J4: 0.19053254 | K4: 0.29230769 | L4: 0 | M4: 0 | N4: 0.99999994 | O4: 0.82713348
A5: 1_Gabriel Joaquim | B5: texto_prompt_0 | C5: command_r_plus_08_2024_temp03 | D5: 0.048696623 | E5: 0.71414721 | F5: 0.69722587 | G5: 0.70558506 | H5: 0.45527452 | I5: 0.12353305 | J5: 0.17396669 | K5: 0.27760642 | L5: 0 | M5: 0 | N5: 0.99999994 | O5: 0.55453807
A6: 1_Gabriel Joaquim | B6: texto_prompt_0 | C6: command_r_plus_08_2024_temp05 | D6: 0.058958918 | E6: 0.71727502 | F6: 0.7088846 | G6: 0.71305513 | H6: 0.47377725 | I6: 0.11563422 | J6: 0.19210371 | K6: 0.27578079 | L6: 0 | M6: 0 | N6: 0.99999994 | O6: 0.55453807
A7: 1_Gabriel Joaquim | B7: texto_prompt_0 | C7: command_r_plus_08_2024_temp07 | D7: 0.044627861 | E7: 0.72755706 | F7: 0.70798439 | G7: 0.71763736 | H7: 0.46191347 | I7: 0.10250153 | J7: 0.18037782 | K7: 0.26447288 | L7: 0 | M7: 0 | N7: 0.99999994 | O7: 0.55453807
A8: 2_Leonardo Maciura | B8: texto_prompt_0 | C8: command_r_plus_08_2024_temp03 | D8: 0.06763447 | E8: 0.73315519 | F8: 0.7267713 | G8: 0.7299493 | H8: 0.47862157 | I8: 0.14185304 | J8: 0.2003829 | K8: 0.27185705 | L8: 0 | M8: 0 | N8: 0.99999994 | O8: 0.99999994
A9: 2_Leonardo Maciura | B9: texto_prompt_0 | C9: command_r_plus_08_2024_temp05 | D9: 0.075685029 | E9: 0.73533142 | F9: 0.73179972 | G9: 0.73356134 | H9: 0.51369446 | I9: 0.14503352 | J9: 0.21180767 | K9: 0.27267194 | L9: 0 | M9: 0 | N9: 0.99999994 | O9: 0.99999994
A10: 2_Leonardo Maciura | B10: texto_prompt_0 | C10: command_r_plus_08_2024_temp07 | D10: 0.06527792 | E10: 0.75196481 | F10: 0.74000585 | G10: 0.74593741 | H10: 0.49653434 | I10: 0.12492114 | J10: 0.19533711 | K10: 0.27851292 | L10: 0 | M10: 0 | N10: 0.99999994 | O10: 0.99999994
A11: 3_Mateus de Andrade | B11: texto_prompt_0 | C11: command_r_plus_08_2024_temp03 | D11: 0.039842204 | E11: 0.713539 | F11: 0.71304846 | G11: 0.71329361 | H11: 0.45076283 | I11: 0.10833333 | J11: 0.18030513 | K11: 0.24271845 | L11: 0 | M11: 0 | N11: 0.99999994 | O11: 0.99999994
A12: 3_Mateus de Andrade | B12: texto_prompt_0 | C12: command_r_plus_08_2024_temp05 | D12: 0.056358129 | E12: 0.72340077 | F12: 0.7280128 | G12: 0.72569942 | H12: 0.45981555 | I12: 0.11741425 | J12: 0.18577075 | K12: 0.27931489 | L12: 0 | M12: 0 | N12: 0.99999994 | O12: 0.99999994
A13: 3_Mateus de Andrade | B13: texto_prompt_0 | C13: command_r_plus_08_2024_temp07 | D13: 0.053237143 | E13: 0.73050904 | F13: 0.72732639 | G13: 0.7289142 | H13: 0.45690834 | I13: 0.11232877 | J13: 0.18331053 | K13: 0.27222982 | L13: 0 | M13: 0 | N13: 0.99999994 | O13: 0.99999994
... A19: 5_Pedro Guilherme | B19: texto_prompt_0 | C19: command_r_plus_08_2024_temp07 | D19: 0.08251863 | E19: 0.74605286 | F19: 0.72877741 | G19: 0.73731399 | H19: 0.51097804 | I19: 0.15722851 | J19: 0.20093147 | K19: 0.29008649 | L19: 0 | M19: 0 | N19: 0.99999994 | O19: 0.99999994

Sheet Gemma
A1: id | B1: modification_type | C1: generator_model | D1: BLEU_score | E1: BERTScore_Precision | F1: BERTScore_Recall | G1: BERTScore_F1 | H1: rouge1 | I1: rouge2 | J1: rougeL | K1: rougeLsum | L1: CTC_groundness | M1: CTC_groundness_ref | N1: CTC_factual | O1: CTC_factual_ref
A2: 0_Ana Luiza | B2: texto_prompt_0 | C2: gemma_27b_temp03 | D2: 0.056423145 | E2: 0.7438938 | F2: 0.7367084 | G2: 0.74028367 | H2: 0.47607053 | I2: 0.15762926 | J2: 0.17884131 | K2: 0.26952141 | L2: 0 | M2: 0 | N2: 0.99999994 | O2: 0.82713348
A3: 0_Ana Luiza | B3: texto_prompt_0 | C3: gemma_27b_temp05 | D3: 0.055889326 | E3: 0.7473039 | F3: 0.73746061 | G3: 0.74234957 | H3: 0.46857143 | I3: 0.15511761 | J3: 0.1752381 | K3: 0.26793651 | L3: 0 | M3: 0 | N3: 0.99999994 | O3: 0.82713348
A4: 0_Ana Luiza | B4: texto_prompt_0 | C4: gemma_27b_temp07 | D4: 0.055889326 | E4: 0.7473039 | F4: 0.73746061 | G4: 0.74234957 | H4: 0.46857143 | I4: 0.15511761 | J4: 0.1752381 | K4: 0.26793651 | L4: 0 | M4: 0 | N4: 0.99999994 | O4: 0.82713348
A5: 0_Ana Luiza | B5: texto_prompt_0 | C5: gemma_9b_temp03 | D5: 0.057153719 | E5: 0.75805134 | F5: 0.75195205 | G5: 0.75498939 | H5: 0.48188175 | I5: 0.15404201 | J5: 0.20470439 | K5: 0.2619199 | L5: 0 | M5: 0 | N5: 0.99999994 | O5: 0.82713348
A6: 0_Ana Luiza | B6: texto_prompt_0 | C6: gemma_9b_temp05 | D6: 0.051347904 | E6: 0.75961924 | F6: 0.74994045 | G6: 0.75474882 | H6: 0.49044586 | I6: 0.16071429 | J6: 0.20382166 | K6: 0.2611465 | L6: 0 | M6: 0 | N6: 0.99999994 | O6: 0.82713348
A7: 0_Ana Luiza | B7: texto_prompt_0 | C7: gemma_9b_temp07 | D7: 0.047294785 | E7: 0.75837189 | F7: 0.74990022 | G7: 0.75411224 | H7: 0.48063033 | I7: 0.16305062 | J7: 0.19829284 | K7: 0.26526592 | L7: 0 | M7: 0 | N7: 0.99999994 | O7: 0.82713348
A8: 1_Gabriel Joaquim | B8: texto_prompt_0 | C8: gemma_27b_temp03 | D8: 0.034471011 | E8: 0.72128767 | F8: 0.70100665 | G8: 0.71100253 | H8: 0.43014945 | I8: 0.097592713 | J8: 0.17283951 | K8: 0.26120858 | L8: 0 | M8: 0 | N8: 0.99999994 | O8: 0.55453807
A9: 1_Gabriel Joaquim | B9: texto_prompt_0 | C9: gemma_27b_temp05 | D9: 0.035039186 | E9: 0.72421813 | F9: 0.70147038 | G9: 0.71266276 | H9: 0.42463958 | I9: 0.099737533 | J9: 0.17300131 | K9: 0.2542595 | L9: 0 | M9: 0 | N9: 0.99999994 | O9: 0.55453807
A10: 1_Gabriel Joaquim | B10: texto_prompt_0 | C10: gemma_27b_temp07 | D10: 0.035039186 | E10: 0.72421813 | F10: 0.70147038 | G10: 0.71266276 | H10: 0.42463958 | I10: 0.099737533 | J10: 0.17300131 | K10: 0.2542595 | L10: 0 | M10: 0 | N10: 0.99999994 | O10: 0.55453807
A11: 1_Gabriel Joaquim | B11: texto_prompt_0 | C11: gemma_9b_temp03 | D11: 0.0454294 | E11: 0.72987622 | F11: 0.70777321 | G11: 0.71865481 | H11: 0.46062992 | I11: 0.11038108 | J11: 0.19685039 | K11: 0.25984252 | L11: 0 | M11: 0 | N11: 0.99999994 | O11: 0.55453807
A12: 1_Gabriel Joaquim | B12: texto_prompt_0 | C12: gemma_9b_temp05 | D12: 0.045469549 | E12: 0.73171371 | F12: 0.70893133 | G12: 0.72014236 | H12: 0.46285339 | I12: 0.11059908 | J12: 0.19723866 | K12: 0.25904011 | L12: 0 | M12: 0 | N12: 0.99999994 | O12: 0.55453807
A13: 1_Gabriel Joaquim | B13: texto_prompt_0 | C13: gemma_9b_temp07 | D13: 0.042147494 | E13: 0.73138142 | F13: 0.70930851 | G13: 0.72017586 | H13: 0.45454545 | I13: 0.11141304 | J13: 0.19131615 | K13: 0.2550882 | L13: 0 | M13: 0 | N13: 0.99999994 | O13: 0.55453807
... A37: 5_Pedro Guilherme | B37: texto_prompt_0 | C37: gemma_9b_temp07 | D37: 0.059558474 | E37: 0.75069857 | F37: 0.72242337 | G37: 0.73628968 | H37: 0.48652695 | I37: 0.14842579 | J37: 0.21107784 | K37: 0.27245509 | L37: 0 | M37: 0 | N37: 0.99999994 | O37: 0.99999994

Sheet GPT
A1: id | B1: modification_type | C1: generator_model | D1: BLEU_score | E1: BERTScore_Precision | F1: BERTScore_Recall | G1: BERTScore_F1 | H1: rouge1 | I1: rouge2 | J1: rougeL | K1: rougeLsum | L1: CTC_groundness | M1: CTC_groundness_ref | N1: CTC_factual | O1: CTC_factual_ref
A2: 0_Ana Luiza | B2: texto_prompt_0 | C2: gpt4o_temp03 | D2: 0.090745485 | E2: 0.75012708 | F2: 0.75142026 | G2: 0.75077313 | H2: 0.53077302 | I2: 0.17841301 | J2: 0.19005416 | K2: 0.28163466 | L2: 0 | M2: 0 | N2: 0.99999994 | O2: 0.82713348
A3: 0_Ana Luiza | B3: texto_prompt_0 | C3: gpt4o_temp05 | D3: 0.094385792 | E3: 0.74998558 | F3: 0.75218433 | G3: 0.75108337 | H3: 0.53071253 | I3: 0.17314314 | J3: 0.19262899 | K3: 0.28206388 | L3: 0 | M3: 0 | N3: 0.99999994 | O3: 0.82713348
A4: 0_Ana Luiza | B4: texto_prompt_0 | C4: gpt4o_temp07 | D4: 0.088738595 | E4: 0.75095534 | F4: 0.7501893 | G4: 0.75057214 | H4: 0.53100597 | I4: 0.1691954 | J4: 0.19384474 | K4: 0.28479559 | L4: 0 | M4: 0 | N4: 0.99999994 | O4: 0.82713348
A5: 1_Gabriel Joaquim | B5: texto_prompt_0 | C5: gpt4o_temp03 | D5: 0.062074551 | E5: 0.73116231 | F5: 0.71673071 | G5: 0.72387457 | H5: 0.48032291 | I5: 0.14444444 | J5: 0.18365288 | K5: 0.25529768 | L5: 0 | M5: 0 | N5: 0.99999994 | O5: 0.55453807
A6: 1_Gabriel Joaquim | B6: texto_prompt_0 | C6: gpt4o_temp05 | D6: 0.062668015 | E6: 0.73713672 | F6: 0.72056663 | G6: 0.7287575 | H6: 0.47935549 | I6: 0.14112903 | J6: 0.18429003 | K6: 0.24974824 | L6: 0 | M6: 0 | N6: 0.99999994 | O6: 0.55453807
A7: 1_Gabriel Joaquim | B7: texto_prompt_0 | C7: gpt4o_temp07 | D7: 0.054286357 | E7: 0.7312398 | F7: 0.71305197 | G7: 0.7220313 | H7: 0.46710526 | I7: 0.12793979 | J7: 0.17481203 | K7: 0.25657895 | L7: 0 | M7: 0 | N7: 0.99999994 | O7: 0.55453807
A8: 2_Leonardo Maciura | B8: texto_prompt_0 | C8: gpt4o_temp03 | D8: 0.10199457 | E8: 0.75177169 | F8: 0.74816132 | G8: 0.74996215 | H8: 0.51452282 | I8: 0.16095535 | J8: 0.19502075 | K8: 0.29045643 | L8: 0 | M8: 0 | N8: 0.99999994 | O8: 0.99999994
A9: 2_Leonardo Maciura | B9: texto_prompt_0 | C9: gpt4o_temp05 | D9: 0.10349588 | E9: 0.75698978 | F9: 0.75039232 | G9: 0.75367653 | H9: 0.51552795 | I9: 0.16683938 | J9: 0.19565217 | K9: 0.28881988 | L9: 0 | M9: 0 | N9: 0.99999994 | O9: 0.99999994
A10: 2_Leonardo Maciura | B10: texto_prompt_0 | C10: gpt4o_temp07 | D10: 0.096394704 | E10: 0.75609577 | F10: 0.74183059 | G10: 0.74889523 | H10: 0.49373192 | I10: 0.16602317 | J10: 0.18997107 | K10: 0.28640309 | L10: 0 | M10: 0 | N10: 0.99999994 | O10: 0.99999994
A11: 3_Mateus de Andrade | B11: texto_prompt_0 | C11: gpt4o_temp03 | D11: 0.055349375 | E11: 0.73778152 | F11: 0.73589826 | G11: 0.7368387 | H11: 0.45812535 | I11: 0.12215436 | J11: 0.18080976 | K11: 0.2384914 | L11: 0 | M11: 0 | N11: 0.99999994 | O11: 0.99999994
A12: 3_Mateus de Andrade | B12: texto_prompt_0 | C12: gpt4o_temp05 | D12: 0.054485462 | E12: 0.74032867 | F12: 0.73979896 | G12: 0.74006373 | H12: 0.45932485 | I12: 0.11745152 | J12: 0.18483675 | K12: 0.24903154 | L12: 0 | M12: 0 | N12: 0.99999994 | O12: 0.99999994
A13: 3_Mateus de Andrade | B13: texto_prompt_0 | C13: gpt4o_temp07 | D13: 0.054416409 | E13: 0.73679405 | F13: 0.73114675 | G13: 0.73395956 | H13: 0.43509492 | I13: 0.11504879 | J13: 0.18060544 | K13: 0.24833248 | L13: 0 | M13: 0 | N13: 0.99999994 | O13: 0.99999994
... A19: 5_Pedro Guilherme | B19: texto_prompt_0 | C19: gpt4o_temp07 | D19: 0.06036187 | E19: 0.74718565 | F19: 0.73581374 | G19: 0.74145615 | H19: 0.49849246 | I19: 0.17002012 | J19: 0.18090452 | K19: 0.27537688 | L19: 0 | M19: 0 | N19: 0.99999994 | O19: 0.99999994

Sheet Llama
A1: id | B1: modification_type | C1: generator_model | D1: BLEU_score | E1: BERTScore_Precision | F1: BERTScore_Recall | G1: BERTScore_F1 | H1: rouge1 | I1: rouge2 | J1: rougeL | K1: rougeLsum | L1: CTC_groundness | M1: CTC_groundness_ref | N1: CTC_factual | O1: CTC_factual_ref
A2: 0_Ana Luiza | B2: texto_prompt_0 | C2: llama_405b_temp03 | D2: 0.066466234 | E2: 0.74499655 | F2: 0.73544496 | G2: 0.74018991 | H2: 0.47584541 | I2: 0.13905683 | J2: 0.19323671 | K2: 0.26690821 | L2: 0 | M2: 0 | N2: 0.99999994 | O2: 0.82713348
A3: 0_Ana Luiza | B3: texto_prompt_0 | C3: llama_405b_temp05 | D3: 0.042994755 | E3: 0.74204338 | F3: 0.73585701 | G3: 0.7389372 | H3: 0.44266667 | I3: 0.13217623 | J3: 0.17733333 | K3: 0.252 | L3: 0 | M3: 0 | N3: 0.76935196 | O3: 0.81532657
A4: 0_Ana Luiza | B4: texto_prompt_0 | C4: llama_405b_temp07 | D4: 0.05260459 | E4: 0.74790078 | F4: 0.72635496 | G4: 0.73697042 | H4: 0.41397849 | I4: 0.11978466 | J4: 0.18145161 | K4: 0.23521505 | L4: 0 | M4: 0 | N4: 0.99999994 | O4: 0.82713348
A5: 0_Ana Luiza | B5: texto_prompt_0 | C5: llama_8b_temp03 | D5: 0.06213829 | E5: 0.73885053 | F5: 0.7320838 | G5: 0.73545158 | H5: 0.48611968 | I5: 0.13094503 | J5: 0.19370759 | K5: 0.23935842 | L5: 0 | M5: 0 | N5: 0.99999994 | O5: 0.82713348
A6: 0_Ana Luiza | B6: texto_prompt_0 | C6: llama_8b_temp05 | D6: 0.055553639 | E6: 0.73885053 | F6: 0.7320838 | G6: 0.73545158 | H6: 0.47361647 | I6: 0.13273196 | J6: 0.18532819 | K6: 0.23294723 | L6: 0 | M6: 0 | N6: 0.99999994 | O6: 0.82713348
A7: 0_Ana Luiza | B7: texto_prompt_0 | C7: llama_8b_temp07 | D7: 0.045373088 | E7: 0.74257421 | F7: 0.73518372 | G7: 0.73886049 | H7: 0.46452477 | I7: 0.13538874 | J7: 0.18340027 | K7: 0.24631861 | L7: 0 | M7: 0 | N7: 0.99999994 | O7: 0.82713348
A8: 1_Gabriel Joaquim | B8: texto_prompt_0 | C8: llama_405b_temp03 | D8: 0.040185484 | E8: 0.72016239 | F8: 0.70007664 | G8: 0.70997751 | H8: 0.43061605 | I8: 0.10841121 | J8: 0.18419415 | K8: 0.25015557 | L8: 0 | M8: 0 | N8: 0.99999994 | O8: 0.55453807
A9: 1_Gabriel Joaquim | B9: texto_prompt_0 | C9: llama_405b_temp05 | D9: 0.034190475 | E9: 0.7186017 | F9: 0.69858062 | G9: 0.70844972 | H9: 0.39972433 | I9: 0.10213941 | J9: 0.18056513 | K9: 0.22742936 | L9: 0 | M9: 0 | N9: 0.76935196 | O9: 0.48749489
A10: 1_Gabriel Joaquim | B10: texto_prompt_0 | C10: llama_405b_temp07 | D10: 0.037631415 | E10: 0.72475362 | F10: 0.69487667 | G10: 0.70950073 | H10: 0.39193885 | I10: 0.10716771 | J10: 0.18346074 | K10: 0.2237665 | L10: 0 | M10: 0 | N10: 0.99999994 | O10: 0.55453807
A11: 1_Gabriel Joaquim | B11: texto_prompt_0 | C11: llama_8b_temp03 | D11: 0.023412628 | E11: 0.71515155 | F11: 0.69363141 | G11: 0.70422709 | H11: 0.4605598 | I11: 0.10573248 | J11: 0.19847328 | K11: 0.23536896 | L11: 0 | M11: 0 | N11: 0.99999994 | O11: 0.55453807
A12: 1_Gabriel Joaquim | B12: texto_prompt_0 | C12: llama_8b_temp05 | D12: 0.021649836 | E12: 0.71515155 | F12: 0.69363141 | G12: 0.70422709 | H12: 0.45049834 | I12: 0.10645376 | J12: 0.20066445 | K12: 0.22724252 | L12: 0 | M12: 0 | N12: 0.99999994 | O12: 0.55453807
A13: 1_Gabriel Joaquim | B13: texto_prompt_0 | C13: llama_8b_temp07 | D13: 0.018599706 | E13: 0.71995127 | F13: 0.69795686 | G13: 0.70878345 | H13: 0.43737024 | I13: 0.10672211 | J13: 0.19515571 | K13: 0.2366782 | L13: 0 | M13: 0 | N13: 0.99999994 | O13: 0.55453807
... A37: 5_Pedro Guilherme | B37: texto_prompt_0 | C37: llama_8b_temp07 | D37: 0.053435262 | E37: 0.73337573 | F37: 0.71826971 | G37: 0.72574419 | H37: 0.517215 | I37: 0.15172414 | J37: 0.19280796 | K37: 0.26625861 | L37: 0 | M37: 0 | N37: 0.99999994 | O37: 0.99999994

Sheet Mixtral
A1: id | B1: modification_type | C1: generator_model | D1: BLEU_score | E1: BERTScore_Precision | F1: BERTScore_Recall | G1: BERTScore_F1 | H1: rouge1 | I1: rouge2 | J1: rougeL | K1: rougeLsum | L1: CTC_groundness | M1: CTC_groundness_ref | N1: CTC_factual | O1: CTC_factual_ref
A2: 0_Ana Luiza | B2: texto_prompt_0 | C2: mixtral_8x22b_temp03 | D2: 0.029430397 | E2: 0.74847782 | F2: 0.73709393 | G2: 0.74274224 | H2: 0.38362069 | I2: 0.12805755 | J2: 0.16954023 | K2: 0.23850575 | L2: 0 | M2: 0 | N2: 0.99999994 | O2: 0.82713348
A3: 0_Ana Luiza | B3: texto_prompt_0 | C3: mixtral_8x22b_temp05 | D3: 0.043361729 | E3: 0.74461603 | F3: 0.73705316 | G3: 0.74081528 | H3: 0.40437158 | I3: 0.12585499 | J3: 0.18032787 | K3: 0.25136612 | L3: 0 | M3: 0 | N3: 0.99999994 | O3: 0.82713348
A4: 0_Ana Luiza | B4: texto_prompt_0 | C4: mixtral_8x22b_temp07 | D4: 0.070487778 | E4: 0.76395571 | F4: 0.74382192 | G4: 0.75375438 | H4: 0.44719687 | I4: 0.14360313 | J4: 0.18644068 | K4: 0.25032595 | L4: 0 | M4: 0 | N4: 0.76935196 | O4: 0.81532657
A5: 0_Ana Luiza | B5: texto_prompt_0 | C5: mixtral_8x7b_temp03 | D5: 0.054134064 | E5: 0.74463999 | F5: 0.73184299 | G5: 0.738186 | H5: 0.4665392 | I5: 0.13401404 | J5: 0.19885277 | K5: 0.26768642 | L5: 0 | M5: 0 | N5: 0.99999994 | O5: 0.82713348
A6: 0_Ana Luiza | B6: texto_prompt_0 | C6: mixtral_8x7b_temp05 | D6: 0.022057002 | E6: 0.7444973 | F6: 0.73199075 | G6: 0.73819107 | H6: 0.38978102 | I6: 0.11403509 | J6: 0.16350365 | K6: 0.22627737 | L6: 0 | M6: 0 | N6: 0.99999994 | O6: 0.82713348
A7: 0_Ana Luiza | B7: texto_prompt_0 | C7: mixtral_8x7b_temp07 | D7: 0.035213148 | E7: 0.73155594 | F7: 0.74213481 | G7: 0.73680741 | H7: 0.42564802 | I7: 0.12704918 | J7: 0.17462483 | K7: 0.24693042 | L7: 0 | M7: 0 | N7: 0.99999994 | O7: 0.82713348
A8: 1_Gabriel Joaquim | B8: texto_prompt_0 | C8: mixtral_8x22b_temp03 | D8: 0.018045276 | E8: 0.71624732 | F8: 0.69162029 | G8: 0.70371842 | H8: 0.37230082 | I8: 0.095451156 | J8: 0.16232316 | K8: 0.21444527 | L8: 0 | M8: 0 | N8: 0.99999994 | O8: 0.55453807
A9: 1_Gabriel Joaquim | B9: texto_prompt_0 | C9: mixtral_8x22b_temp05 | D9: 0.040168805 | E9: 0.73271084 | F9: 0.70712805 | G9: 0.71969217 | H9: 0.39858657 | I9: 0.11606511 | J9: 0.18091873 | K9: 0.23321555 | L9: 0 | M9: 0 | N9: 0.99999994 | O9: 0.55453807
A10: 1_Gabriel Joaquim | B10: texto_prompt_0 | C10: mixtral_8x22b_temp07 | D10: 0.045682241 | E10: 0.7391147 | F10: 0.70435071 | G10: 0.72131407 | H10: 0.40673401 | I10: 0.10788941 | J10: 0.17643098 | K10: 0.24107744 | L10: 0 | M10: 0 | N10: 0.76935196 | O10: 0.48749489
A11: 1_Gabriel Joaquim | B11: texto_prompt_0 | C11: mixtral_8x7b_temp03 | D11: 0.03786532 | E11: 0.72632504 | F11: 0.70061564 | G11: 0.71323872 | H11: 0.44473684 | I11: 0.11462451 | J11: 0.17894737 | K11: 0.25526316 | L11: 0 | M11: 0 | N11: 0.99999994 | O11: 0.55453807
A12: 1_Gabriel Joaquim | B12: texto_prompt_0 | C12: mixtral_8x7b_temp05 | D12: 0.020104206 | E12: 0.72621441 | F12: 0.70055008 | G12: 0.7131514 | H12: 0.37395912 | I12: 0.10462472 | J12: 0.1665405 | K12: 0.21801665 | L12: 0 | M12: 0 | N12: 0.99999994 | O12: 0.55453807
A13: 1_Gabriel Joaquim | B13: texto_prompt_0 | C13: mixtral_8x7b_temp07 | D13: 0.020553179 | E13: 0.72305673 | F13: 0.70580155 | G13: 0.71432495 | H13: 0.3895554 | I13: 0.084805654 | J13: 0.17360621 | K13: 0.23288638 | L13: 0 | M13: 0 | N13: 0.99999994 | O13: 0.55453807
... A37: 5_Pedro Guilherme | B37: texto_prompt_0 | C37: mixtral_8x7b_temp07 | D37: 0.045301866 | E37: 0.72879648 | F37: 0.71742785 | G37: 0.72306752 | H37: 0.47224394 | I37: 0.13469068 | J37: 0.17044566 | K37: 0.26114152 | L37: 0 | M37: 0 | N37: 0.99999994 | O37: 0.99999994

Sheet Phi
A1: id | B1: modification_type | C1: generator_model | D1: BLEU_score | E1: BERTScore_Precision | F1: BERTScore_Recall | G1: BERTScore_F1 | H1: rouge1 | I1: rouge2 | J1: rougeL | K1: rougeLsum | L1: CTC_groundness | M1: CTC_groundness_ref | N1: CTC_factual | O1: CTC_factual_ref
A2: 0_Ana Luiza | B2: texto_prompt_0 | C2: phi_3.5_vision_temp03 | D2: 0.011364789 | E2: 0.75121677 | F2: 0.73051333 | G2: 0.74072045 | H2: 0.31086439 | I2: 0.10643368 | J2: 0.13798573 | K2: 0.19191118 | L2: 0 | M2: 0 | N2: 0.76935196 | O2: 0.81532657
A3: 0_Ana Luiza | B3: texto_prompt_0 | C3: phi_3.5_vision_temp05 | D3: 0.011364789 | E3: 0.75121677 | F3: 0.73051333 | G3: 0.74072045 | H3: 0.31086439 | I3: 0.10643368 | J3: 0.13798573 | K3: 0.19191118 | L3: 0 | M3: 0 | N3: 0.76935196 | O3: 0.81532657
A4: 0_Ana Luiza | B4: texto_prompt_0 | C4: phi_3.5_vision_temp07 | D4: 0.012332305 | E4: 0.75276965 | F4: 0.73368764 | G4: 0.74310613 | H4: 0.3223835 | I4: 0.096403979 | J4: 0.15278839 | K4: 0.19404125 | L4: 0 | M4: 0 | N4: 0.76935196 | O4: 0.81532657
A5: 0_Ana Luiza | B5: texto_prompt_0 | C5: phi_3_mini_temp03 | D5: 0.014001339 | E5: 0.74561805 | F5: 0.73733658 | G5: 0.74145412 | H5: 0.36119403 | I5: 0.10164425 | J5: 0.16567164 | K5: 0.21492537 | L5: 0.7023139 | M5: 0.6929934 | N5: 0.7023139 | O5: 0.6929934
A6: 0_Ana Luiza | B6: texto_prompt_0 | C6: phi_3_mini_temp05 | D6: 0.022982491 | E6: 0.74618888 | F6: 0.73134822 | G6: 0.73869401 | H6: 0.35610465 | I6: 0.097525473 | J6: 0.16133721 | K6: 0.21366279 | L6: 0 | M6: 0 | N6: 0.76935196 | O6: 0.81532657
A7: 0_Ana Luiza | B7: texto_prompt_0 | C7: phi_3_mini_temp07 | D7: 0.021697156 | E7: 0.7289598 | F7: 0.72899503 | G7: 0.72897738 | H7: 0.35678749 | I7: 0.095373665 | J7: 0.16062544 | K7: 0.21321962 | L7: 0.82713348 | M7: 1 | N7: 0.82713348 | O7: 1
A8: 1_Gabriel Joaquim | B8: texto_prompt_0 | C8: phi_3.5_vision_temp03 | D8: 0.011668953 | E8: 0.73847437 | F8: 0.70169783 | G8: 0.71961653 | H8: 0.30363036 | I8: 0.085950413 | J8: 0.15016502 | K8: 0.19471947 | L8: 0 | M8: 0 | N8: 0.76935196 | O8: 0.48749489
A9: 1_Gabriel Joaquim | B9: texto_prompt_0 | C9: phi_3.5_vision_temp05 | D9: 0.011668953 | E9: 0.73847437 | F9: 0.70169783 | G9: 0.71961653 | H9: 0.30363036 | I9: 0.085950413 | J9: 0.15016502 | K9: 0.19471947 | L9: 0 | M9: 0 | N9: 0.76935196 | O9: 0.48749489
A10: 1_Gabriel Joaquim | B10: texto_prompt_0 | C10: phi_3.5_vision_temp07 | D10: 0.011709434 | E10: 0.72817445 | F10: 0.68907416 | G10: 0.70808494 | H10: 0.32222222 | I10: 0.079491256 | J10: 0.16190476 | K10: 0.18888889 | L10: 0 | M10: 0 | N10: 0.76935196 | O10: 0.48749489
A11: 1_Gabriel Joaquim | B11: texto_prompt_0 | C11: phi_3_mini_temp03 | D11: 0.010740672 | E11: 0.71537161 | F11: 0.70161891 | G11: 0.7084285 | H11: 0.33152595 | I11: 0.057408844 | J11: 0.15956623 | K11: 0.21068939 | L11: 0.7023139 | M11: 0.64298242 | N11: 0.7023139 | O11: 0.64298242
A12: 1_Gabriel Joaquim | B12: texto_prompt_0 | C12: phi_3_mini_temp05 | D12: 0.023489843 | E12: 0.73593438 | F12: 0.69905102 | G12: 0.71701866 | H12: 0.32253203 | I12: 0.078490566 | J12: 0.1582517 | K12: 0.19894499 | L12: 0 | M12: 0 | N12: 0.76935196 | O12: 0.48749489
A13: 1_Gabriel Joaquim | B13: texto_prompt_0 | C13: phi_3_mini_temp07 | D13: 0.021098599 | E13: 0.72127712 | F13: 0.70578432 | G13: 0.71344668 | H13: 0.3460972 | I13: 0.081120944 | J13: 0.14874816 | K13: 0.20913108 | L13: 0.82713348 | M13: 0.52113158 | N13: 0.82713348 | O13: 0.52113158
... A37: 5_Pedro Guilherme | B37: texto_prompt_0 | C37: phi_3_mini_temp07 | D37: 0.03166702 | E37: 0.73391688 | F37: 0.72191018 | G37: 0.72786403 | H37: 0.42622951 | I37: 0.11330049 | J37: 0.16721311 | K37: 0.25409836 | L37: 0.82713348 | M37: 0.82713348 | N37: 0.82713348 | O37: 0.82713348

Sheet Qwen
A1: id | B1: modification_type | C1: generator_model | D1: BLEU_score | E1: BERTScore_Precision | F1: BERTScore_Recall | G1: BERTScore_F1 | H1: rouge1 | I1: rouge2 | J1: rougeL | K1: rougeLsum | L1: CTC_groundness | M1: CTC_groundness_ref | N1: CTC_factual | O1: CTC_factual_ref
A2: 0_Ana Luiza | B2: texto_prompt_0 | C2: qwen2_72b_temp03 | D2: 0.049276347 | E2: 0.75200194 | F2: 0.74108434 | G2: 0.74650323 | H2: 0.414651 | I2: 0.12179931 | J2: 0.17415342 | K2: 0.25431928 | L2: 0 | M2: 0 | N2: 0.99999994 | O2: 0.82713348
A3: 0_Ana Luiza | B3: texto_prompt_0 | C3: qwen2_72b_temp05 | D3: 0.042797601 | E3: 0.75470948 | F3: 0.75222206 | G3: 0.75346375 | H3: 0.39059159 | I3: 0.1184868 | J3: 0.16963649 | K3: 0.23948681 | L3: 0.7023139 | M3: 0.6929934 | N3: 0.7023139 | O3: 0.6929934
A4: 0_Ana Luiza | B4: texto_prompt_0 | C4: qwen2_72b_temp07 | D4: 0.034798505 | E4: 0.75449336 | F4: 0.74671829 | G4: 0.75058573 | H4: 0.39942322 | I4: 0.12851986 | J4: 0.16438356 | K4: 0.23071377 | L4: 0 | M4: 0 | N4: 0.99999994 | O4: 0.82713348
A5: 0_Ana Luiza | B5: texto_prompt_0 | C5: qwen2_7b_temp03 | D5: 0.015387035 | E5: 0.66962481 | F5: 0.65530962 | G5: 0.66238981 | H5: 0.32114467 | I5: 0.10191083 | J5: 0.15739269 | K5: 0.16693164 | L5: 0 | M5: 0 | N5: 0.82775801 | O5: 0.84644145
A6: 0_Ana Luiza | B6: texto_prompt_0 | C6: qwen2_7b_temp05 | D6: 0.015387035 | E6: 0.66962481 | F6: 0.65530962 | G6: 0.66238981 | H6: 0.32114467 | I6: 0.10191083 | J6: 0.15739269 | K6: 0.16693164 | L6: 0 | M6: 0 | N6: 0.82775801 | O6: 0.84644145
A7: 0_Ana Luiza | B7: texto_prompt_0 | C7: qwen2_7b_temp07 | D7: 0.022099407 | E7: 0.74341667 | F7: 0.72392589 | G7: 0.73354179 | H7: 0.35752483 | I7: 0.10711553 | J7: 0.16042781 | K7: 0.21237586 | L7: 0 | M7: 0 | N7: 0.82775801 | O7: 0.84644145
A8: 1_Gabriel Joaquim | B8: texto_prompt_0 | C8: qwen2_72b_temp03 | D8: 0.020319524 | E8: 0.72958308 | F8: 0.70751858 | G8: 0.71838146 | H8: 0.37625179 | I8: 0.08739255 | J8: 0.17167382 | K8: 0.2260372 | L8: 0 | M8: 0 | N8: 0.99999994 | O8: 0.55453807
A9: 1_Gabriel Joaquim | B9: texto_prompt_0 | C9: qwen2_72b_temp05 | D9: 0.032264429 | E9: 0.73906934 | F9: 0.71619368 | G9: 0.72745168 | H9: 0.3648449 | I9: 0.10502959 | J9: 0.16100443 | K9: 0.22895126 | L9: 0.7023139 | M9: 0.64298242 | N9: 0.7023139 | O9: 0.64298242
A10: 1_Gabriel Joaquim | B10: texto_prompt_0 | C10: qwen2_72b_temp07 | D10: 0.018762653 | E10: 0.73484927 | F10: 0.71477288 | G10: 0.72467202 | H10: 0.37219731 | I10: 0.085329341 | J10: 0.16442451 | K10: 0.2122571 | L10: 0 | M10: 0 | N10: 0.99999994 | O10: 0.55453807
A11: 1_Gabriel Joaquim | B11: texto_prompt_0 | C11: qwen2_7b_temp03 | D11: 0 | E11: 0.65038788 | F11: 0.63013124 | G11: 0.64009935 | H11: 0.30769231 | I11: 0.077879039 | J11: 0.15053763 | K11: 0.20016543 | L11: 0 | M11: 0 | N11: 0.82775801 | O11: 0.56720084
